<?xml version='1.0'?>

<robot name="My_bot" xmlns:xacro="http://www.ros.org/wiki/xacro">
  <xacro:include filename="$(find slam_project)/urdf/My_bot.gazebo" />
  <link name="robot_footprint"></link>

  <joint name="robot_footprint_joint" type="fixed">
    <origin xyz="0 0 0" rpy="0 0 0" />
    <parent link="robot_footprint"/>
    <child link="chassis" />
  </joint>

  <link name='chassis'>
    <pose>0 0 0.1 0 0 0</pose>

    <inertial>
      <mass value="15.0"/>
      <origin xyz="0.0 0 0" rpy=" 0 0 0"/>
      <inertia
          ixx="0.1" ixy="0" ixz="0"
          iyy="0.1" iyz="0"
          izz="0.1"
      />
    </inertial>

    <collision name='collision'>
      <origin xyz="0 0 0" rpy=" 0 0 0"/> 
      <geometry>
        <box size=".3 .4 .01"/>
      </geometry>
    </collision>

    <visual name='chassis_visual'>
      <origin xyz="0 0 0" rpy=" 0 0 0"/>
      <geometry>
        <box size=".3 .2 .01"/>
      </geometry>
    </visual>
    <collision name='laser_support'>
       <origin xyz="0.05 0 0.05" rpy=" 0 0 0"/> 
       <geometry>
         <cylinder length="0.1" radius="0.02"/>
       </geometry>
    </collision>
    <visual name='laser_support'>
      <origin xyz="0.05 0 0.05" rpy=" 0 0 0"/>
      <geometry>
        <cylinder length="0.1" radius="0.02"/>
      </geometry>
    </visual>
  </link>
  <link name='front_left_wheel'>
    
    <inertial>
      <mass value="5.0"/>
      <origin xyz="0.0 0 0" rpy=" 0 1.5707 1.5707"/>
      <inertia
          ixx="0.1" ixy="0" ixz="0"
          iyy="0.1" iyz="0"
          izz="0.1"
      />
    </inertial>
    <collision name='collision'>
       <origin xyz="0 0 0" rpy=" 0 1.5707 1.5707"/> 
       <geometry>
         <cylinder length="0.05" radius="0.1"/>
       </geometry>
    </collision>
    <visual name='left_wheel_visual'>
      <origin xyz="0 0 0" rpy=" 0 1.5707 1.5707"/>
      <geometry>
        <cylinder length="0.05" radius="0.1"/>
      </geometry>
    </visual>
      
  </link>
  <link name='rear_left_wheel'>
    
    <inertial>
      <mass value="5.0"/>
      <origin xyz="0.0 0 0" rpy=" 0 1.5707 1.5707"/>
      <inertia
          ixx="0.1" ixy="0" ixz="0"
          iyy="0.1" iyz="0"
          izz="0.1"
      />
    </inertial>
    <collision name='collision'>
       <origin xyz="0 0 0" rpy=" 0 1.5707 1.5707"/> 
       <geometry>
         <cylinder length="0.05" radius="0.1"/>
       </geometry>
    </collision>
    <visual name='left_wheel_visual'>
      <origin xyz="0 0 0" rpy=" 0 1.5707 1.5707"/>
      <geometry>
        <cylinder length="0.05" radius="0.1"/>
      </geometry>
    </visual>
      
  </link>
  <link name='front_right_wheel'>
    
    <inertial>
      <mass value="5.0"/>
      <origin xyz="0.0 0 0" rpy=" 0 1.5707 1.5707"/>
      <inertia
          ixx="0.1" ixy="0" ixz="0"
          iyy="0.1" iyz="0"
          izz="0.1"
      />
    </inertial>
    <collision name='collision'>
       <origin xyz="0 0 0" rpy=" 0 1.5707 1.5707"/> 
       <geometry>
          <cylinder length="0.05" radius="0.1"/>
       </geometry>
    </collision>
    <visual name='right_wheel_visual'>
      <origin xyz="0 0 0" rpy=" 0 1.5707 1.5707"/>
      <geometry>
         <cylinder length="0.05" radius="0.1"/>
      </geometry>
    </visual>
      
  </link>
  <link name='rear_right_wheel'>
    
    <inertial>
      <mass value="5.0"/>
      <origin xyz="0.0 0 0" rpy=" 0 1.5707 1.5707"/>
      <inertia
          ixx="0.1" ixy="0" ixz="0"
          iyy="0.1" iyz="0"
          izz="0.1"
      />
    </inertial>
    <collision name='collision'>
       <origin xyz="0 0 0" rpy=" 0 1.5707 1.5707"/> 
       <geometry>
          <cylinder length="0.05" radius="0.1"/>
       </geometry>
    </collision>
    <visual name='right_wheel_visual'>
      <origin xyz="0 0 0" rpy=" 0 1.5707 1.5707"/>
      <geometry>
         <cylinder length="0.05" radius="0.1"/>
      </geometry>
    </visual>
      
  </link>
 <joint name="camera_optical_joint" type="fixed">
  	<origin xyz="0 0 0" rpy="${-pi/2} 0 ${-pi/2}"/>
	<parent link="camera"/>
	<child link="camera_link_optical"/>
  </joint>

  <link name='camera_link_optical'>
  </link>	
  <link name='camera'>
    
    <inertial>
      <mass value="0.1"/>
      <origin xyz="0.0 0 0" rpy=" 0 1.5707 1.5707"/>
      <inertia
          ixx="0.1" ixy="0" ixz="0"
          iyy="0.1" iyz="0"
          izz="0.1"
      />
    </inertial>
    <collision name='collision'>
       <origin xyz="0 0 0" rpy=" 0 1.5707 1.5707"/> 
       <geometry>
         <box size="0.05 0.05 0.05"/>
       </geometry>
    </collision>
    <visual name='camera_visual'>
      <origin xyz="0 0 0" rpy=" 0 1.5707 1.5707"/>
      <geometry>
        <box size="0.05 0.05 0.05"/>
      </geometry>
    </visual>
      
  </link>
  
  
  
  <link name='hokuyo'>
    
    <inertial>
      <mass value="0.05"/>
      <origin xyz="0.0 0 0" rpy=" 0 0 0"/>
      <inertia
          ixx="0.1" ixy="0" ixz="0"
          iyy="0.1" iyz="0"
          izz="0.1"
      />
    </inertial>
    <collision name='collision'>
       <origin xyz="0 0 0" rpy=" 0 0 0"/> 
       <geometry>
         <cylinder radius="0.03" length="0.05"/>
       </geometry>
    </collision>
    <visual name='hokuyo_visual'>
      <origin xyz="0 0 0" rpy=" 0 0 0"/>
      <geometry>
        <mesh filename="package://udacity_bot/meshes/hokuyo.dae"/> 
      </geometry>
      <materiel>
	<color rgba="0 0 0 1"/>
      </materiel>
    </visual>

      
  </link>
  <joint type="fixed" name="hokuyo_joint">
    <origin xyz="0.05 0 0.12" rpy="0 0 0"/>
    <child link="hokuyo"/>
    <parent link="chassis"/>
  </joint>
  
  
  <joint type="fixed" name="camera_joint">
    <origin xyz="0.18 0 0" rpy="0 0 0"/>
    <child link="camera"/>
    <parent link="chassis"/>
    <axis xyz="0 1 0" rpy="0 0 0"/>
  </joint>
 
  <joint type="continuous" name="front_left_wheel_hinge">
    <origin xyz="0.1 0.13 0.0" rpy="0 0 0"/>
    <child link="front_left_wheel"/>
    <parent link="chassis"/>
    <axis xyz="0 1 0" rpy="0 0 0"/>
    <limit effort="10000" velocity="1000"/>
    <dynamics damping="1.0" friction="1.0"/>
  </joint>
  <joint type="continuous" name="rear_left_wheel_hinge">
    <origin xyz="-0.1 0.13 0.0" rpy="0 0 0"/>
    <child link="rear_left_wheel"/>
    <parent link="chassis"/>
    <axis xyz="0 1 0" rpy="0 0 0"/>
    <limit effort="10000" velocity="1000"/>
    <dynamics damping="1.0" friction="1.0"/>
  </joint>
  <joint type="continuous" name="front_right_wheel_hinge">
    <origin xyz="0.1 -0.13 0" rpy="0 0 0"/>
    <child link="front_right_wheel"/>
    <parent link="chassis"/>
    <axis xyz="0 1 0" rpy="0 0 0"/>
    <limit effort="10000" velocity="1000"/>
    <dynamics damping="1.0" friction="1.0"/>
  </joint>
  <joint type="continuous" name="rear_right_wheel_hinge">
    <origin xyz="-0.1 -0.13 0" rpy="0 0 0"/>
    <child link="rear_right_wheel"/>
    <parent link="chassis"/>
    <axis xyz="0 1 0" rpy="0 0 0"/>
    <limit effort="10000" velocity="1000"/>
    <dynamics damping="1.0" friction="1.0"/>
  </joint>

</robot>
